Workbook

Sheet 11.2.2-catch
A1: Year | B1: 0 | C1: 1 | D1: 2 | E1: 3
A2: 1974 | B2: 6029179 | C2: 41247793 | D2: 4717275 | E2: 573197
A3: 1975 | B3: 6670522 | C3: 47021275 | D3: 16637746 | E3: 493175
A4: 1976 | B4: 17286283 | C4: 67897908 | D4: 4769430 | E4: 277806
A5: 1977 | B5: 21067473 | C5: 19534117 | D5: 11061896 | E5: 215236
A6: 1978 | B6: 12126361 | C6: 47503062 | D6: 2756102 | E6: 243071
A7: 1979 | B7: 8515090 | C7: 54622008 | D7: 3129084 | E7: 206489
A8: 1980 | B8: 2536060 | C8: 27519328 | D8: 29331610 | E8: 2469205
A9: 1981 | B9: 843662 | C9: 19717227 | D9: 4828293 | E9: 342688
A10: 1982 | B10: 3894967 | C10: 11773432 | D10: 1719454 | E10: 123737
A11: 1983 | B11: 9687209 | C11: 4750434 | D11: 1565548 | E11: 246765
A12: 1984 | B12: 1881718 | C12: 9622782 | D12: 675537 | E12: 8388
A13: 1985 | B13: 84760 | C13: 2096317 | D13: 2993626 | E13: 69234
... A52: 2024 | B52: 9763444 | C52: 3463141 | D52: 929439 | E52: 94406

Sheet 11.2.3-weight
A1: Year | B1: Season | C1: age0 | D1: age1 | E1: age2 | F1: age3
A2: 1974 | B2: 2 | C2: 0.0058 | D2: 0.0089 | E2: 0.015 | F2: 0.0197
A3: 1975 | B3: 2 | C3: 0.0075 | D3: 0.0111 | E3: 0.0168 | F3: 0.0216
A4: 1976 | B4: 2 | C4: 0.0043 | D4: 0.009 | E4: 0.0153 | F4: 0.019
A5: 1977 | B5: 2 | C5: 0.0059 | D5: 0.011 | E5: 0.0146 | F5: 0.0196
A6: 1978 | B6: 2 | C6: 0.0044 | D6: 0.0103 | E6: 0.0155 | F6: 0.0196
A7: 1979 | B7: 2 | C7: 0.0057 | D7: 0.0105 | E7: 0.015 | F7: 0.0173
A8: 1980 | B8: 2 | C8: 0.0051 | D8: 0.0052 | E8: 0.0069 | F8: 0.0083
A9: 1981 | B9: 2 | C9: 0.0082 | D9: 0.0126 | E9: 0.0153 | F9: 0.0194
A10: 1982 | B10: 2 | C10: 0.0071 | D10: 0.011 | E10: 0.016 | F10: 0.0219
A11: 1983 | B11: 2 | C11: 0.0042 | D11: 0.0124 | E11: 0.0169 | F11: 0.0211
A12: 1984 | B12: 2 | C12: 0.0053 | D12: 0.0122 | E12: 0.0168 | F12: 0.0164
A13: 1985 | B13: 2 | C13: 0.0051 | D13: 0.0093 | E13: 0.0135 | F13: 0.0197
... A52: 2024 | B52: 2 | C52: 0.0046 | D52: 0.0085 | E52: 0.0123 | F52: 0.0133

Sheet 11.6.1-nat mort
A1: Year | B1: age0 | C1: age1 | D1: age2 | E1: age3
A2: 1974 | B2: 1.3949 | C2: 1.1583 | D2: 1.0423 | E2: 0.9923
A3: 1975 | B3: 1.4239 | C3: 1.2021 | D3: 1.0813 | E3: 1.0313
A4: 1976 | B4: 1.429 | C4: 1.2097 | D4: 1.0894 | E4: 1.046
A5: 1977 | B5: 1.376 | C5: 1.179 | D5: 1.059 | E5: 1.0223
A6: 1978 | B6: 1.2557 | C6: 1.095 | D6: 0.9876 | E6: 0.951
A7: 1979 | B7: 1.3193 | C7: 1.2107 | D7: 1.0721 | E7: 1.0427
A8: 1980 | B8: 1.3673 | C8: 1.236 | D8: 1.0804 | E8: 1.0367
A9: 1981 | B9: 1.3324 | C9: 1.2167 | D9: 1.059 | E9: 0.9833
A10: 1982 | B10: 1.1804 | C10: 1.0303 | D10: 0.9163 | E10: 0.82
A11: 1983 | B11: 1.1584 | C11: 0.9983 | D11: 0.876 | E11: 0.7913
A12: 1984 | B12: 1.2266 | C12: 1.0414 | D12: 0.9103 | E12: 0.8256
A13: 1985 | B13: 1.3466 | C13: 1.1503 | D13: 0.9719 | E13: 0.8926
... A52: 2024 | B52: 1.4472 | C52: 1.3794 | D52: 1.252 | E52: 1.252

Sheet 11.6.3Num
A1: Year | B1: 0 | C1: 1 | D1: 2 | E1: 3
A2: 1974 | B2: 25074100 | C2: 131919000 | D2: 2724560 | E2: 4978830
A3: 1975 | B3: 32668800 | C3: 165674000 | D3: 1294110 | E3: 5944570
A4: 1976 | B4: 15101300 | C4: 73923700 | D4: 1552380 | E4: 685683
A5: 1977 | B5: 26184600 | C5: 126987000 | D5: 7566240 | E5: 976795
A6: 1978 | B6: 45249800 | C6: 233152000 | D6: 1940230 | E6: 908210
A7: 1979 | B7: 24881200 | C7: 125247000 | D7: 4378110 | E7: 7900520
A8: 1980 | B8: 14138100 | C8: 91984900 | D8: 3270520 | E8: 632308
A9: 1981 | B9: 40895600 | C9: 24363900 | D9: 2713430 | E9: 24198
A10: 1982 | B10: 24809300 | C10: 8280430 | D10: 3488130 | E10: 27879
A11: 1983 | B11: 33274800 | C11: 4842840 | D11: 1121230 | E11: 37094
A12: 1984 | B12: 16297200 | C12: 8109380 | D12: 722709 | E12: 99737
A13: 1985 | B13: 10690900 | C13: 3335350 | D13: 1283310 | E13: 99363
... A52: 2024 | B52: 18239400 | C52: 93071300 | D52: 5419530 | E52: 477335

Sheet 11.9.1 -maturity
A1: year | B1: Age0 | C1: Age1 | D1: Age2 | E1: Age3
A2: 1974 | B2: 0 | C2: 0.4093 | D2: 0.8719 | E2: 0.9468
A3: 1975 | B3: 0 | C3: 0.4093 | D3: 0.8719 | E3: 0.9468
A4: 1976 | B4: 0 | C4: 0.4093 | D4: 0.8719 | E4: 0.9468
A5: 1977 | B5: 0 | C5: 0.4093 | D5: 0.8719 | E5: 0.9468
A6: 1978 | B6: 0 | C6: 0.4093 | D6: 0.8719 | E6: 0.9468
A7: 1979 | B7: 0 | C7: 0.4093 | D7: 0.8719 | E7: 0.9468
A8: 1980 | B8: 0 | C8: 0.4093 | D8: 0.8719 | E8: 0.9468
A9: 1981 | B9: 0 | C9: 0.4093 | D9: 0.8719 | E9: 0.9468
A10: 1982 | B10: 0 | C10: 0.4093 | D10: 0.8719 | E10: 0.9468
A11: 1983 | B11: 0 | C11: 0.4093 | D11: 0.8719 | E11: 0.9468
A12: 1984 | B12: 0 | C12: 0.4093 | D12: 0.8719 | E12: 0.9468
A13: 1985 | B13: 0 | C13: 0.4093 | D13: 0.8719 | E13: 0.9468
... A52: 2024 | B52: 0 | C52: 0.4093 | D52: 0.8719 | E52: 0.9468

Sheet FM Estimated
A1: This table usies the F(1-2) from Table 11.6.4 and then offsets age 0 and age 3 by the average deviation that I calculated over to the right
A2: year | B2: 0 | C2: 1 | D2: 2 | E2: 3 | H2: These are proportions of catch/numbers | O2: These are instantaneous, if the value was > 1 I made the F be 2. | W2: What is the proption of F at age 2
A3: ='11.6.3Num'!A2 -> 1974 | B3: =C3*$W$208 -> 0.2156999 | C3: 1.152 | D3: 1.152 | E3: =D3*$Z$208 -> 1.8032085 | H3: Year | I3: Season | J3: 0 | K3: 1 | L3: 2 | M3: 3 | O3: 0 | P3: 1 | Q3: 2 | R3: 3
A4: ='11.6.3Num'!A3 -> 1975 | B4: =C4*$W$208 -> 0.33160115 | C4: 1.771 | D4: 1.771 | E4: =D4*$Z$208 -> 2.7721201 | H4: 1974 | I4: 1 | J4: 0 | K4: 0.13413862 | L4: 0.19250449 | M4: 0.86184102 | O4: 0 | P4: 0.12553116 | Q4: 0.17510938 | R4: 0.57761625 | W4: =IF($Q4>0,O4/$Q4,"") -> 0 | X4: =IF($Q4>0,P4/$Q4,"") -> 0.71687285 | Y4: =IF($Q4>0,Q4/$Q4,"") -> 1 | Z4: =IF($Q4>0,R4/$Q4,"") -> 3.2986025
A5: ='11.6.3Num'!A4 -> 1976 | B5: =C5*$W$208 -> 0.34751651 | C5: 1.856 | D5: 1.856 | E5: =D5*$Z$208 -> 2.9051693 | H5: 1974 | I5: 2 | J5: 0.0075143116 | K5: 0.19322666 | L5: 0.17401659 | M5: 0.18481701 | O5: 0.0074861497 | P5: 0.17570488 | Q5: 0.15971704 | R5: 0.16874362 | W5: =IF($Q5>0,O5/$Q5,"") -> 0.046871328 | X5: =IF($Q5>0,P5/$Q5,"") -> 1.100101 | Y5: =IF($Q5>0,Q5/$Q5,"") -> 1 | Z5: =IF($Q5>0,R5/$Q5,"") -> 1.0565161
A6: ='11.6.3Num'!A5 -> 1977 | B6: =C6*$W$208 -> 0.33834177 | C6: 1.807 | D6: 1.807 | E6: =D6*$Z$208 -> 2.8284703 | H6: 1974 | I6: 3 | J6: 0.016472079 | K6: 0.29340907 | L6: 0.65449611 | M6: 0.33253411 | O6: 0.016337156 | P6: 0.25428297 | Q6: 0.48029613 | R6: 0.28289579 | W6: =IF($Q6>0,O6/$Q6,"") -> 0.034014757 | X6: =IF($Q6>0,P6/$Q6,"") -> 0.52942957 | Y6: =IF($Q6>0,Q6/$Q6,"") -> 1 | Z6: =IF($Q6>0,R6/$Q6,"") -> 0.58900286
A7: ='11.6.3Num'!A6 -> 1978 | B7: =C7*$W$208 -> 0.23049182 | C7: 1.231 | D7: 1.231 | E7: =D7*$Z$208 -> 1.9268661 | H7: 1974 | I7: 4 | J7: 0.0098722019 | K7: 0.092173232 | L7: 0.25827951 | M7: 0.25556494 | O7: 0.0098236317 | P7: 0.088052842 | Q7: 0.22762069 | R7: 0.22552116 | W7: =IF($Q7>0,O7/$Q7,"") -> 0.043157903 | X7: =IF($Q7>0,P7/$Q7,"") -> 0.38684024 | Y7: =IF($Q7>0,Q7/$Q7,"") -> 1 | Z7: =IF($Q7>0,R7/$Q7,"") -> 0.99077621
A8: ='11.6.3Num'!A7 -> 1979 | B8: =C8*$W$208 -> 0.14454889 | C8: 0.772 | D8: 0.772 | E8: =D8*$Z$208 -> 1.2084002 | H8: 1975 | I8: 1 | J8: 0.0004864748 | K8: 0.29525134 | L8: 0.55285431 | M8: 0.32949779 | O8: 0.00048635649 | P8: 0.25565552 | Q8: 0.42469464 | R8: 0.28071513 | W8: =IF($Q8>0,O8/$Q8,"") -> 0.001145191 | X8: =IF($Q8>0,P8/$Q8,"") -> 0.60197491 | Y8: =IF($Q8>0,Q8/$Q8,"") -> 1 | Z8: =IF($Q8>0,R8/$Q8,"") -> 0.66098109
A9: ='11.6.3Num'!A8 -> 1980 | B9: =C9*$W$208 -> 0.44862584 | C9: 2.396 | D9: 2.396 | E9: =D9*$Z$208 -> 3.7504233 | H9: 1975 | I9: 2 | J9: 0.0036106836 | K9: 0.38263089 | L9: 0.73654024 | M9: 0.58920958 | O9: 0.0036041729 | P9: 0.31793539 | Q9: 0.52123252 | R9: 0.44523439 | W9: =IF($Q9>0,O9/$Q9,"") -> 0.0069147122 | X9: =IF($Q9>0,P9/$Q9,"") -> 0.60996844 | Y9: =IF($Q9>0,Q9/$Q9,"") -> 1 | Z9: =IF($Q9>0,R9/$Q9,"") -> 0.85419534
A10: ='11.6.3Num'!A9 -> 1981 | B10: =C10*$W$208 -> 0.20877204 | C10: 1.115 | D10: 1.115 | E10: =D10*$Z$208 -> 1.745293 | H10: 1975 | I10: 3 | J10: 0.023480913 | K10: 0.23928946 | L10: 1.5725206 | M10: 1.0671547 | O10: 0.023207381 | P10: 0.21281301 | Q10: =P10 -> 0.21281301 | R10: =Q10 -> 0.21281301 | W10: =IF($Q10>0,O10/$Q10,"") -> 0.10905058 | X10: =IF($Q10>0,P10/$Q10,"") -> 1 | Y10: =IF($Q10>0,Q10/$Q10,"") -> 1 | Z10: =IF($Q10>0,R10/$Q10,"") -> 1
A11: ='11.6.3Num'!A10 -> 1982 | B11: =C11*$W$208 -> 0.17169862 | C11: 0.917 | D11: 0.917 | E11: =D11*$Z$208 -> 1.4353665 | H11: 1975 | I11: 4 | J11: 0 | K11: 0 | L11: 0 | M11: 0 | O11: 0 | P11: 0 | Q11: 0 | R11: 0 | W11: =IF($Q11>0,O11/$Q11,"") | X11: =IF($Q11>0,P11/$Q11,"") | Y11: =IF($Q11>0,Q11/$Q11,"") | Z11: =IF($Q11>0,R11/$Q11,"")
A12: ='11.6.3Num'!A11 -> 1983 | B12: =C12*$W$208 -> 0.29265533 | C12: 1.563 | D12: 1.563 | E12: =D12*$Z$208 -> 2.4465407 | H12: 1976 | I12: 1 | J12: 0.0092458294 | K12: 0.35914396 | L12: 0.30821603 | M12: 0.29460723 | O12: 0.0092032182 | P12: 0.30172618 | Q12: 0.26524343 | R12: 0.25517593 | W12: =IF($Q12>0,O12/$Q12,"") -> 0.034697253 | X12: =IF($Q12>0,P12/$Q12,"") -> 1.1375444 | Y12: =IF($Q12>0,Q12/$Q12,"") -> 1 | Z12: =IF($Q12>0,R12/$Q12,"") -> 0.96204431
A13: ='11.6.3Num'!A12 -> 1984 | B13: =C13*$W$208 -> 0.15091503 | C13: 0.806 | D13: 0.806 | E13: =D13*$Z$208 -> 1.2616199 | H13: 1976 | I13: 2 | J13: 0.049265004 | K13: 0.38969599 | L13: 0.52351696 | M13: 0.40248567 | O13: 0.048071168 | P13: 0.32273726 | Q13: 0.40756669 | R13: 0.33134408 | W13: =IF($Q13>0,O13/$Q13,"") -> 0.11794676 | X13: =IF($Q13>0,P13/$Q13,"") -> 0.7918637 | Y13: =IF($Q13>0,Q13/$Q13,"") -> 1 | Z13: =IF($Q13>0,R13/$Q13,"") -> 0.81298126
A14: ='11.6.3Num'!A13 -> 1985 | B14: =C14*$W$208 -> 0.22056813 | C14: 1.178 | D14: 1.178 | E14: =D14*$Z$208 -> 1.8439059 | H14: 1976 | I14: 3 | J14: 0.075318407 | K14: 0.28240437 | L14: 0.39032323 | M14: 0.18269782 | O14: 0.072551866 | P14: 0.24603126 | Q14: 0.32316193 | R14: 0.16698016 | W14: =IF($Q14>0,O14/$Q14,"") -> 0.22450623 | X14: =IF($Q14>0,P14/$Q14,"") -> 0.76132502 | Y14: =IF($Q14>0,Q14/$Q14,"") -> 1 | Z14: =IF($Q14>0,R14/$Q14,"") -> 0.51670739
A15: ='11.6.3Num'!A14 -> 1986 | B15: =C15*$W$208 -> 0.18255851 | C15: 0.975 | D15: 0.975 | E15: =D15*$Z$208 -> 1.5261531 | H15: 1976 | I15: 4 | J15: 0 | K15: 0 | L15: 0 | M15: 0 | O15: 0 | P15: 0 | Q15: 0 | R15: 0 | W15: =IF($Q15>0,O15/$Q15,"") | X15: =IF($Q15>0,P15/$Q15,"") | Y15: =IF($Q15>0,Q15/$Q15,"") | Z15: =IF($Q15>0,R15/$Q15,"")
A16: ='11.6.3Num'!A15 -> 1987 | B16: =C16*$W$208 -> 0.059354921 | C16: 0.317 | D16: 0.317 | E16: =D16*$Z$208 -> 0.4961954 | H16: 1977 | I16: 1 | J16: 0.0070824773 | K16: 0.2437338 | L16: 0.46137731 | M16: 0.37163423 | O16: 0.0070574556 | P16: 0.21630378 | Q16: 0.36958523 | R16: 0.31039357 | W16: =IF($Q16>0,O16/$Q16,"") -> 0.019095611 | X16: =IF($Q16>0,P16/$Q16,"") -> 0.58526088 | Y16: =IF($Q16>0,Q16/$Q16,"") -> 1 | Z16: =IF($Q16>0,R16/$Q16,"") -> 0.839843
A17: ='11.6.3Num'!A16 -> 1988 | B17: =C17*$W$208 -> 0.21270407 | C17: 1.136 | D17: 1.136 | E17: =D17*$Z$208 -> 1.778164 | H17: 1977 | I17: 2 | J17: 0.0096242906 | K17: 0.20992274 | L17: 0.89868708 | M17: 0.58289917 | O17: 0.0095781254 | P17: 0.18935313 | Q17: 0.5928962 | R17: 0.44172252 | W17: =IF($Q17>0,O17/$Q17,"") -> 0.01615481 | X17: =IF($Q17>0,P17/$Q17,"") -> 0.31936978 | Y17: =IF($Q17>0,Q17/$Q17,"") -> 1 | Z17: =IF($Q17>0,R17/$Q17,"") -> 0.74502506
A18: ='11.6.3Num'!A17 -> 1989 | B18: =C18*$W$208 -> 0.055235652 | C18: 0.295 | D18: 0.295 | E18: =D18*$Z$208 -> 0.46175913 | H18: 1977 | I18: 3 | J18: 0.089984207 | K18: 0.15152747 | L18: 2.2531606 | M18: 1.4662275 | O18: 0.086054381 | P18: 0.14060572 | Q18: =P18 -> 0.14060572 | R18: =Q18 -> 0.14060572 | W18: =IF($Q18>0,O18/$Q18,"") -> 0.61202617 | X18: =IF($Q18>0,P18/$Q18,"") -> 1 | Y18: =IF($Q18>0,Q18/$Q18,"") -> 1 | Z18: =IF($Q18>0,R18/$Q18,"") -> 1
A19: ='11.6.3Num'!A18 -> 1990 | B19: =C19*$W$208 -> 0.26400769 | C19: 1.41 | D19: 1.41 | E19: =D19*$Z$208 -> 2.2070521 | H19: 1977 | I19: 4 | J19: 0 | K19: 0 | L19: 0 | M19: 0 | O19: 0 | P19: 0 | Q19: 0 | R19: 0 | W19: =IF($Q19>0,O19/$Q19,"") | X19: =IF($Q19>0,P19/$Q19,"") | Y19: =IF($Q19>0,Q19/$Q19,"") | Z19: =IF($Q19>0,R19/$Q19,"")
A20: ='11.6.3Num'!A19 -> 1991 | B20: =C20*$W$208 -> 0.11440333 | C20: 0.611 | D20: 0.611 | E20: =D20*$Z$208 -> 0.95638924 | H20: 1978 | I20: 1 | J20: 0.00072488778 | K20: 0.35394913 | L20: 0.07757103 | M20: 0.23706102 | O20: 0.00072462511 | P20: 0.29808933 | Q20: 0.074638706 | R20: 0.21105685 | W20: =IF($Q20>0,O20/$Q20,"") -> 0.0097084361 | X20: =IF($Q20>0,P20/$Q20,"") -> 3.9937634 | Y20: =IF($Q20>0,Q20/$Q20,"") -> 1 | Z20: =IF($Q20>0,R20/$Q20,"") -> 2.8277132
A21: ='11.6.3Num'!A20 -> 1992 | B21: =C21*$W$208 -> 0.14567233 | C21: 0.778 | D21: 0.778 | E21: =D21*$Z$208 -> 1.2177919 | H21: 1978 | I21: 2 | J21: 0.012193789 | K21: 0.2163853 | L21: 0.4742481 | M21: 0.58491975 | O21: 0.012119746 | P21: 0.19457509 | Q21: 0.37764717 | R21: 0.44284943 | W21: =IF($Q21>0,O21/$Q21,"") -> 0.032092775 | X21: =IF($Q21>0,P21/$Q21,"") -> 0.51522983 | Y21: =IF($Q21>0,Q21/$Q21,"") -> 1 | Z21: =IF($Q21>0,R21/$Q21,"") -> 1.1726539
A22: ='11.6.3Num'!A21 -> 1993 | B22: =C22*$W$208 -> 0.26101186 | C22: 1.394 | D22: 1.394 | E22: =D22*$Z$208 -> 2.1820075 | H22: 1978 | I22: 3 | J22: 0.019429687 | K22: 0.17138297 | L22: 1.2321434 | M22: 0.43984311 | O22: 0.019242147 | P22: 0.15750114 | Q22: =P22 -> 0.15750114 | R22: 0.35586253 | W22: =IF($Q22>0,O22/$Q22,"") -> 0.12217148 | X22: =IF($Q22>0,P22/$Q22,"") -> 1 | Y22: =IF($Q22>0,Q22/$Q22,"") -> 1 | Z22: =IF($Q22>0,R22/$Q22,"") -> 2.2594283
A23: ='11.6.3Num'!A22 -> 1994 | B23: =C23*$W$208 -> 0.12732286 | C23: 0.68 | D23: 0.68 | E23: =D23*$Z$208 -> 1.0643939 | H23: 1978 | I23: 4 | J23: 0 | K23: 0 | L23: 0 | M23: 0 | O23: 0 | P23: 0 | Q23: 0 | R23: 0 | W23: =IF($Q23>0,O23/$Q23,"") | X23: =IF($Q23>0,P23/$Q23,"") | Y23: =IF($Q23>0,Q23/$Q23,"") | Z23: =IF($Q23>0,R23/$Q23,"")
A24: ='11.6.3Num'!A23 -> 1995 | B24: =C24*$W$208 -> 0.24210067 | C24: 1.293 | D24: 1.293 | E24: =D24*$Z$208 -> 2.0239137 | H24: 1979 | I24: 1 | J24: 0.010170828 | K24: 0.21422852 | L24: 0.043832359 | M24: 0.2520148 | O24: 0.01011928 | P24: 0.19283609 | Q24: 0.042885604 | R24: 0.22276677 | W24: =IF($Q24>0,O24/$Q24,"") -> 0.23595983 | X24: =IF($Q24>0,P24/$Q24,"") -> 4.4965226 | Y24: =IF($Q24>0,Q24/$Q24,"") -> 1 | Z24: =IF($Q24>0,R24/$Q24,"") -> 5.1944416
A25: ='11.6.3Num'!A24 -> 1996 | B25: =C25*$W$208 -> 0.20633793 | C25: 1.102 | D25: 1.102 | E25: =D25*$Z$208 -> 1.7249443 | H25: 1979 | I25: 2 | J25: 0.0042317895 | K25: 0.11512671 | L25: 0.27242017 | M25: 0.24439201 | O25: 0.0042228481 | P25: 0.10874679 | Q25: 0.23846578 | R25: 0.21681944 | W25: =IF($Q25>0,O25/$Q25,"") -> 0.017708403 | X25: =IF($Q25>0,P25/$Q25,"") -> 0.45602683 | Y25: =IF($Q25>0,Q25/$Q25,"") -> 1 | Z25: =IF($Q25>0,R25/$Q25,"") -> 0.90922664
A26: ='11.6.3Num'!A25 -> 1997 | B26: =C26*$W$208 -> 0.1479192 | C26: 0.79 | D26: 0.79 | E26: =D26*$Z$208 -> 1.2365753 | H26: 1979 | I26: 3 | J26: 0.022705127 | K26: 0.10206838 | L26: 0.089024818 | M26: 0.21606238 | O26: 0.022449305 | P26: 0.097032199 | Q26: 0.08517713 | R26: 0.19431496 | W26: =IF($Q26>0,O26/$Q26,"") -> 0.26356024 | X26: =IF($Q26>0,P26/$Q26,"") -> 1.1391814 | Y26: =IF($Q26>0,Q26/$Q26,"") -> 1 | Z26: =IF($Q26>0,R26/$Q26,"") -> 2.2813043
A27: ='11.6.3Num'!A26 -> 1998 | B27: =C27*$W$208 -> 0.27074831 | C27: 1.446 | D27: 1.446 | E27: =D27*$Z$208 -> 2.2634024 | H27: 1979 | I27: 4 | J27: 0 | K27: 0 | L27: 0 | M27: 0 | O27: 0 | P27: 0 | Q27: 0 | R27: 0 | W27: =IF($Q27>0,O27/$Q27,"") | X27: =IF($Q27>0,P27/$Q27,"") | Y27: =IF($Q27>0,Q27/$Q27,"") | Z27: =IF($Q27>0,R27/$Q27,"")
A28: ='11.6.3Num'!A27 -> 1999 | B28: =C28*$W$208 -> 0.14548509 | C28: 0.777 | D28: 0.777 | E28: =D28*$Z$208 -> 1.2162266 | H28: 1980 | I28: 1 | J28: 0 | K28: 0.15478147 | L28: 0.5326786 | M28: 0.7434809 | O28: 0 | P28: 0.14339765 | Q28: 0.41296956 | R28: 0.52454398 | W28: =IF($Q28>0,O28/$Q28,"") -> 0 | X28: =IF($Q28>0,P28/$Q28,"") -> 0.3472354 | Y28: =IF($Q28>0,Q28/$Q28,"") -> 1 | Z28: =IF($Q28>0,R28/$Q28,"") -> 1.2701759
A29: ='11.6.3Num'!A28 -> 2000 | B29: =C29*$W$208 -> 0.24659442 | C29: 1.317 | D29: 1.317 | E29: =D29*$Z$208 -> 2.0614806 | H29: 1980 | I29: 2 | J29: 0 | K29: 0.28193485 | L29: 1.2876209 | M29: 1.6236609 | O29: 0 | P29: 0.24567717 | Q29: =P29 -> 0.24567717 | R29: =Q29 -> 0.24567717 | W29: =IF($Q29>0,O29/$Q29,"") -> 0 | X29: =IF($Q29>0,P29/$Q29,"") -> 1 | Y29: =IF($Q29>0,Q29/$Q29,"") -> 1 | Z29: =IF($Q29>0,R29/$Q29,"") -> 1
A30: ='11.6.3Num'!A29 -> 2001 | B30: =C30*$W$208 -> 0.24453478 | C30: 1.306 | D30: 1.306 | E30: =D30*$Z$208 -> 2.0442624 | H30: 1980 | I30: 3 | J30: 0.027214448 | K30: 0.27562744 | L30: 0.30013017 | M30: 0.11027683 | O30: 0.026847472 | P30: 0.24090431 | Q30: 0.2592782 | R30: 0.10441382 | W30: =IF($Q30>0,O30/$Q30,"") -> 0.10354697 | X30: =IF($Q30>0,P30/$Q30,"") -> 0.92913447 | Y30: =IF($Q30>0,Q30/$Q30,"") -> 1 | Z30: =IF($Q30>0,R30/$Q30,"") -> 0.40270961
A31: ='11.6.3Num'!A30 -> 2002 | B31: =C31*$W$208 -> 0.27187175 | C31: 1.452 | D31: 1.452 | E31: =D31*$Z$208 -> 2.2727941 | H31: 1980 | I31: 4 | J31: 0 | K31: 0 | L31: 0 | M31: 0 | O31: 0 | P31: 0 | Q31: 0 | R31: 0 | W31: =IF($Q31>0,O31/$Q31,"") | X31: =IF($Q31>0,P31/$Q31,"") | Y31: =IF($Q31>0,Q31/$Q31,"") | Z31: =IF($Q31>0,R31/$Q31,"")
A32: ='11.6.3Num'!A31 -> 2003 | B32: =C32*$W$208 -> 0.21869573 | C32: 1.168 | D32: 1.168 | E32: =D32*$Z$208 -> 1.8282531 | H32: 1981 | I32: 1 | J32: 0.0070085831 | K32: 0.25230823 | L32: 0.24168947 | M32: 0.2568551 | O32: 0.0069840802 | P32: 0.22299479 | Q32: 0.2147 | R32: 0.22651972 | W32: =IF($Q32>0,O32/$Q32,"") -> 0.032529484 | X32: =IF($Q32>0,P32/$Q32,"") -> 1.0386343 | Y32: =IF($Q32>0,Q32/$Q32,"") -> 1 | Z32: =IF($Q32>0,R32/$Q32,"") -> 1.0550523
A33: ='11.6.3Num'!A32 -> 2004 | B33: =C33*$W$208 -> 0.32748188 | C33: 1.749 | D33: 1.749 | E33: =D33*$Z$208 -> 2.7376838 | H33: 1981 | I33: 2 | J33: 0.00099355432 | K33: 0.14532718 | L33: 1.1149317 | M33: 0.83495739 | O33: 0.00099306091 | P33: 0.13526068 | Q33: =P33 -> 0.13526068 | R33: 0.56610703 | W33: =IF($Q33>0,O33/$Q33,"") -> 0.0073418298 | X33: =IF($Q33>0,P33/$Q33,"") -> 1 | Y33: =IF($Q33>0,Q33/$Q33,"") -> 1 | Z33: =IF($Q33>0,R33/$Q33,"") -> 4.1853037
A34: ='11.6.3Num'!A33 -> 2005 | B34: =C34*$W$208 -> 0.21738506 | C34: 1.161 | D34: 1.161 | E34: =D34*$Z$208 -> 1.8172961 | H34: 1981 | I34: 3 | J34: 0.013305295 | K34: 0.2780245 | L34: 0.33338755 | M34: 0.11688852 | O34: 0.013217171 | P34: 0.24272173 | Q34: 0.28350754 | R34: 0.11031563 | W34: =IF($Q34>0,O34/$Q34,"") -> 0.046620175 | X34: =IF($Q34>0,P34/$Q34,"") -> 0.85613855 | Y34: =IF($Q34>0,Q34/$Q34,"") -> 1 | Z34: =IF($Q34>0,R34/$Q34,"") -> 0.38911004
A35: ='11.6.3Num'!A34 -> 2006 | B35: =C35*$W$208 -> 0.25670535 | C35: 1.371 | D35: 1.371 | E35: =D35*$Z$208 -> 2.146006 | H35: 1981 | I35: 4 | J35: 0 | K35: 0 | L35: 0 | M35: 0 | O35: 0 | P35: 0 | Q35: 0 | R35: 0 | W35: =IF($Q35>0,O35/$Q35,"") | X35: =IF($Q35>0,P35/$Q35,"") | Y35: =IF($Q35>0,Q35/$Q35,"") | Z35: =IF($Q35>0,R35/$Q35,"")
A36: ='11.6.3Num'!A35 -> 2007 | B36: =C36*$W$208 -> 0.23442385 | C36: 1.252 | D36: 1.252 | E36: =D36*$Z$208 -> 1.959737 | H36: 1982 | I36: 1 | J36: 0.014695346 | K36: 0.40702925 | L36: 0.082243081 | M36: 0.12090036 | O36: 0.014587897 | P36: 0.33437528 | Q36: 0.078951958 | R36: 0.11387775 | W36: =IF($Q36>0,O36/$Q36,"") -> 0.18476928 | X36: =IF($Q36>0,P36/$Q36,"") -> 4.235174 | Y36: =IF($Q36>0,Q36/$Q36,"") -> 1 | Z36: =IF($Q36>0,R36/$Q36,"") -> 1.4423676
A37: ='11.6.3Num'!A36 -> 2008 | B37: =C37*$W$208 -> 0.18667778 | C37: 0.997 | D37: 0.997 | E37: =D37*$Z$208 -> 1.5605893 | H37: 1982 | I37: 2 | J37: 0.032992668 | K37: 0.60637938 | L37: 0.30702984 | M37: 0.19847271 | O37: 0.032454346 | P37: 0.4546783 | Q37: 0.26437135 | R37: 0.18001785 | W37: =IF($Q37>0,O37/$Q37,"") -> 0.12276045 | X37: =IF($Q37>0,P37/$Q37,"") -> 1.7198471 | Y37: =IF($Q37>0,Q37/$Q37,"") -> 1 | Z37: =IF($Q37>0,R37/$Q37,"") -> 0.68092798
A38: ='11.6.3Num'!A37 -> 2009 | B38: =C38*$W$208 -> 0.11627573 | C38: 0.621 | D38: 0.621 | E38: =D38*$Z$208 -> 0.9720421 | H38: 1982 | I38: 3 | J38: 0.1391137 | K38: 0.075999788 | L38: 0.031915342 | M38: 0.030193237 | O38: 0.12987091 | P38: 0.073183597 | Q38: 0.031411423 | R38: 0.029741974 | W38: =IF($Q38>0,O38/$Q38,"") -> 4.1345122 | X38: =IF($Q38>0,P38/$Q38,"") -> 2.3298402 | Y38: =IF($Q38>0,Q38/$Q38,"") -> 1 | Z38: =IF($Q38>0,R38/$Q38,"") -> 0.94685217
A39: ='11.6.3Num'!A38 -> 2010 | B39: =C39*$W$208 -> 0.133689 | C39: 0.714 | D39: 0.714 | E39: =D39*$Z$208 -> 1.1176136 | H39: 1982 | I39: 4 | J39: 0 | K39: 0 | L39: 0 | M39: 0 | O39: 0 | P39: 0 | Q39: 0 | R39: 0 | W39: =IF($Q39>0,O39/$Q39,"") | X39: =IF($Q39>0,P39/$Q39,"") | Y39: =IF($Q39>0,Q39/$Q39,"") | Z39: =IF($Q39>0,R39/$Q39,"")
A40: ='11.6.3Num'!A39 -> 2011 | B40: =C40*$W$208 -> 0.11365437 | C40: 0.607 | D40: 0.607 | E40: =D40*$Z$208 -> 0.9501281 | H40: 1983 | I40: 1 | J40: 0.11113146 | K40: 0.25433422 | L40: 0.30968007 | M40: 0.16914686 | O40: 0.10517889 | P40: 0.22456741 | Q40: 0.26631835 | R40: 0.15561511 | W40: =IF($Q40>0,O40/$Q40,"") -> 0.39493671 | X40: =IF($Q40>0,P40/$Q40,"") -> 0.84322919 | Y40: =IF($Q40>0,Q40/$Q40,"") -> 1 | Z40: =IF($Q40>0,R40/$Q40,"") -> 0.5843199
...

Sheet 11.6.3 Num quart long
A1: Year | B1: season | C1: 0 | D1: 1 | E1: 2 | F1: 3
A2: 1974 | B2: 1 | C2: 395307000 | D2: 120033000 | E2: 11198300 | F2: 551857
A3: 1974 | B3: 2 | C3: 250741000 | D3: 59743900 | E3: 4978830 | F3: 260950
A4: 1974 | B4: 3 | C4: 172577000 | D4: 37801500 | E4: 2041320 | F4: 103851
A5: 1974 | B5: 4 | C5: 131919000 | D5: 27245600 | E5: 1390420 | F5: 57997
A6: 1975 | B6: 1 | C6: 515815000 | D6: 93898000 | E6: 18183000 | F6: 789632
A7: 1975 | B7: 2 | C7: 326688000 | D7: 38005000 | E7: 5944570 | F7: 283103
A8: 1975 | B8: 3 | C8: 223161000 | D8: 19875000 | E8: 1403340 | F8: 62021
A9: 1975 | B9: 4 | C9: 165674000 | D9: 12941100 | E9: 802936 | F9: 24884
A10: 1976 | B10: 1 | C10: 231803000 | D10: 117529000 | E10: 9372170 | F10: 614082
A11: 1976 | B11: 2 | C11: 151013000 | D11: 48147100 | E11: 3081350 | F11: 220142
A12: 1976 | B12: 3 | C12: 102278000 | D12: 24522800 | E12: 685683 | F12: 45370
A13: 1976 | B13: 4 | C13: 73923700 | D13: 15523800 | E13: 380388 | F13: 17448
... A19: 1978 | B19: 2 | C19: 452498000 | D19: 47808100 | E19: 2550530 | F19: 199506
A20: 1978 | B20: 3 | C20: 316763000 | D20: 29020200 | E20: 908210 | F20: 68072
A21: 1978 | B21: 4 | C21: 233152000 | D21: 19402300 | E21: 569270 | F21: 33757
A22: 1979 | B22: 1 | C22: 351927000 | D22: 172091000 | E22: 14693300 | F22: 464810
A23: 1979 | B23: 2 | C23: 248812000 | D23: 98638700 | E23: 7900520 | F23: 259362
A24: 1979 | B24: 3 | C24: 171009000 | D24: 62695800 | E24: 3738070 | F24: 120169
A25: 1979 | B25: 4 | C25: 125247000 | D25: 43781100 | E25: 2548250 | F25: 70876
A26: 1980 | B26: 1 | C26: 206302000 | D26: 91984900 | E26: 32705200 | F26: 1992070
A27: 1980 | B27: 2 | C27: 141381000 | D27: 33394800 | E27: 8947180 | F27: 603214
A28: 1980 | B28: 3 | C28: 93188000 | D28: 14028400 | E28: 1298350 | F28: 79110
A29: 1980 | B29: 4 | C29: 66477100 | D29: 8193420 | E29: 632308 | F29: 23992
A30: 1981 | B30: 1 | C30: 61178700 | D30: 48838800 | E30: 6136970 | F30: 509256
A31: 1981 | B31: 2 | C31: 40895600 | D31: 24363900 | E31: 2713430 | F31: 241986
A32: 1981 | B32: 3 | C32: 28128200 | D32: 13862300 | E32: 959133 | F32: 84140
A33: 1981 | B33: 4 | C33: 20871900 | D33: 9578760 | E33: 625520 | F33: 44058
... A41: 1983 | B41: 4 | C41: 19052300 | D41: 1816870 | E41: 179111 | F41: 40190
A42: 1984 | B42: 1 | C42: 24950900 | D42: 15082300 | E42: 1489010 | F42: 187938
A43: 1984 | B43: 2 | C43: 16297200 | D43: 8109380 | E43: 722709 | F43: 99737
A44: 1984 | B44: 3 | C44: 11589000 | D44: 5274980 | E44: 330577 | F44: 44732
A45: 1984 | B45: 4 | C45: 9076570 | D45: 3936670 | E45: 240425 | F45: 27594
A46: 1985 | B46: 1 | C46: 16828500 | D46: 7132750 | E46: 3192060 | F46: 225817
A47: 1985 | B47: 2 | C47: 10690900 | D47: 3335350 | E47: 1283310 | F47: 99363
A48: 1985 | B48: 3 | C48: 7046980 | D48: 1826770 | E48: 420912 | F48: 31522
A49: 1985 | B49: 4 | C49: 5400390 | D49: 1306250 | E49: 280757 | F49: 16465
A50: 1986 | B50: 1 | C50: 60994900 | D50: 4214240 | E50: 1056360 | F50: 255480
A51: 1986 | B51: 2 | C51: 37757300 | D51: 2015000 | E51: 448552 | F51: 118190
A52: 1986 | B52: 3 | C52: 24298500 | D52: 1130680 | E52: 164680 | F52: 43094
...

Sheet FM don't use
A1: These are proportions… | H1: These are instantaneous, if the value was > 1 I made the F be 2. | P1: What is the proption of F at age 2
A2: Year | B2: Season | C2: 0 | D2: 1 | E2: 2 | F2: 3 | H2: 0 | I2: 1 | J2: 2 | K2: 3
A3: 1974 | B3: 1 | C3: ='[1]11.2.2-catch'!C2/'11.6.3 Num quart long'!C2 -> 0 | D3: ='[1]11.2.2-catch'!D2/'11.6.3 Num quart long'!D2 -> 0.13413862 | E3: ='[1]11.2.2-catch'!E2/'11.6.3 Num quart long'!E2 -> 0.19250449 | F3: ='[1]11.2.2-catch'!F2/'11.6.3 Num quart long'!F2 -> 0.86184102 | H3: =IF(C3<1,1-EXP(-C3),2) -> 0 | I3: =IF(D3<1,1-EXP(-D3),2) -> 0.12553116 | J3: =IF(E3<1,1-EXP(-E3),2) -> 0.17510938 | K3: =IF(F3<1,1-EXP(-F3),2) -> 0.57761625 | P3: =IF($J3=0,"",H3/$J3) -> 0 | Q3: =IF($J3=0,"",I3/$J3) -> 0.71687285 | R3: =IF($J3=0,"",J3/$J3) -> 1 | S3: =IF($J3=0,"",K3/$J3) -> 3.2986025
A4: 1974 | B4: 2 | C4: ='[1]11.2.2-catch'!C3/'11.6.3 Num quart long'!C3 -> 0.0075143116 | D4: ='[1]11.2.2-catch'!D3/'11.6.3 Num quart long'!D3 -> 0.19322666 | E4: ='[1]11.2.2-catch'!E3/'11.6.3 Num quart long'!E3 -> 0.17401659 | F4: ='[1]11.2.2-catch'!F3/'11.6.3 Num quart long'!F3 -> 0.18481701 | H4: =IF(C4<1,1-EXP(-C4),2) -> 0.0074861497 | I4: =IF(D4<1,1-EXP(-D4),2) -> 0.17570488 | J4: =IF(E4<1,1-EXP(-E4),2) -> 0.15971704 | K4: =IF(F4<1,1-EXP(-F4),2) -> 0.16874362 | P4: =IF($J4=0,"",H4/$J4) -> 0.046871328 | Q4: =IF($J4=0,"",I4/$J4) -> 1.100101 | R4: =IF($J4=0,"",J4/$J4) -> 1 | S4: =IF($J4=0,"",K4/$J4) -> 1.0565161
A5: 1974 | B5: 3 | C5: ='[1]11.2.2-catch'!C4/'11.6.3 Num quart long'!C4 -> 0.016472079 | D5: ='[1]11.2.2-catch'!D4/'11.6.3 Num quart long'!D4 -> 0.29340907 | E5: ='[1]11.2.2-catch'!E4/'11.6.3 Num quart long'!E4 -> 0.65449611 | F5: ='[1]11.2.2-catch'!F4/'11.6.3 Num quart long'!F4 -> 0.33253411 | H5: =IF(C5<1,1-EXP(-C5),2) -> 0.016337156 | I5: =IF(D5<1,1-EXP(-D5),2) -> 0.25428297 | J5: =IF(E5<1,1-EXP(-E5),2) -> 0.48029613 | K5: =IF(F5<1,1-EXP(-F5),2) -> 0.28289579 | P5: =IF($J5=0,"",H5/$J5) -> 0.034014757 | Q5: =IF($J5=0,"",I5/$J5) -> 0.52942957 | R5: =IF($J5=0,"",J5/$J5) -> 1 | S5: =IF($J5=0,"",K5/$J5) -> 0.58900286
A6: 1974 | B6: 4 | C6: ='[1]11.2.2-catch'!C5/'11.6.3 Num quart long'!C5 -> 0.0098722019 | D6: ='[1]11.2.2-catch'!D5/'11.6.3 Num quart long'!D5 -> 0.092173232 | E6: ='[1]11.2.2-catch'!E5/'11.6.3 Num quart long'!E5 -> 0.25827951 | F6: ='[1]11.2.2-catch'!F5/'11.6.3 Num quart long'!F5 -> 0.25556494 | H6: =IF(C6<1,1-EXP(-C6),2) -> 0.0098236317 | I6: =IF(D6<1,1-EXP(-D6),2) -> 0.088052842 | J6: =IF(E6<1,1-EXP(-E6),2) -> 0.22762069 | K6: =IF(F6<1,1-EXP(-F6),2) -> 0.22552116 | P6: =IF($J6=0,"",H6/$J6) -> 0.043157903 | Q6: =IF($J6=0,"",I6/$J6) -> 0.38684024 | R6: =IF($J6=0,"",J6/$J6) -> 1 | S6: =IF($J6=0,"",K6/$J6) -> 0.99077621
A7: 1975 | B7: 1 | C7: ='[1]11.2.2-catch'!C6/'11.6.3 Num quart long'!C6 -> 0.0004864748 | D7: ='[1]11.2.2-catch'!D6/'11.6.3 Num quart long'!D6 -> 0.29525134 | E7: ='[1]11.2.2-catch'!E6/'11.6.3 Num quart long'!E6 -> 0.55285431 | F7: ='[1]11.2.2-catch'!F6/'11.6.3 Num quart long'!F6 -> 0.32949779 | H7: =IF(C7<1,1-EXP(-C7),2) -> 0.00048635649 | I7: =IF(D7<1,1-EXP(-D7),2) -> 0.25565552 | J7: =IF(E7<1,1-EXP(-E7),2) -> 0.42469464 | K7: =IF(F7<1,1-EXP(-F7),2) -> 0.28071513 | P7: =IF($J7=0,"",H7/$J7) -> 0.001145191 | Q7: =IF($J7=0,"",I7/$J7) -> 0.60197491 | R7: =IF($J7=0,"",J7/$J7) -> 1 | S7: =IF($J7=0,"",K7/$J7) -> 0.66098109
A8: 1975 | B8: 2 | C8: ='[1]11.2.2-catch'!C7/'11.6.3 Num quart long'!C7 -> 0.0036106836 | D8: ='[1]11.2.2-catch'!D7/'11.6.3 Num quart long'!D7 -> 0.38263089 | E8: ='[1]11.2.2-catch'!E7/'11.6.3 Num quart long'!E7 -> 0.73654024 | F8: ='[1]11.2.2-catch'!F7/'11.6.3 Num quart long'!F7 -> 0.58920958 | H8: =IF(C8<1,1-EXP(-C8),2) -> 0.0036041729 | I8: =IF(D8<1,1-EXP(-D8),2) -> 0.31793539 | J8: =IF(E8<1,1-EXP(-E8),2) -> 0.52123252 | K8: =IF(F8<1,1-EXP(-F8),2) -> 0.44523439 | P8: =IF($J8=0,"",H8/$J8) -> 0.0069147122 | Q8: =IF($J8=0,"",I8/$J8) -> 0.60996844 | R8: =IF($J8=0,"",J8/$J8) -> 1 | S8: =IF($J8=0,"",K8/$J8) -> 0.85419534
A9: 1975 | B9: 3 | C9: ='[1]11.2.2-catch'!C8/'11.6.3 Num quart long'!C8 -> 0.023480913 | D9: ='[1]11.2.2-catch'!D8/'11.6.3 Num quart long'!D8 -> 0.23928946 | E9: ='[1]11.2.2-catch'!E8/'11.6.3 Num quart long'!E8 -> 1.5725206 | F9: ='[1]11.2.2-catch'!F8/'11.6.3 Num quart long'!F8 -> 1.0671547 | H9: =IF(C9<1,1-EXP(-C9),2) -> 0.023207381 | I9: =IF(D9<1,1-EXP(-D9),2) -> 0.21281301 | J9: =IF(E9<1,1-EXP(-E9),2) -> 2 | K9: =IF(F9<1,1-EXP(-F9),2) -> 2 | P9: =IF($J9=0,"",H9/$J9) -> 0.011603691 | Q9: =IF($J9=0,"",I9/$J9) -> 0.1064065 | R9: =IF($J9=0,"",J9/$J9) -> 1 | S9: =IF($J9=0,"",K9/$J9) -> 1
A10: 1975 | B10: 4 | C10: ='[1]11.2.2-catch'!C9/'11.6.3 Num quart long'!C9 -> 0 | D10: ='[1]11.2.2-catch'!D9/'11.6.3 Num quart long'!D9 -> 0 | E10: ='[1]11.2.2-catch'!E9/'11.6.3 Num quart long'!E9 -> 0 | F10: ='[1]11.2.2-catch'!F9/'11.6.3 Num quart long'!F9 -> 0 | H10: =IF(C10<1,1-EXP(-C10),2) -> 0 | I10: =IF(D10<1,1-EXP(-D10),2) -> 0 | J10: =IF(E10<1,1-EXP(-E10),2) -> 0 | K10: =IF(F10<1,1-EXP(-F10),2) -> 0 | P10: =IF($J10=0,"",H10/$J10) | Q10: =IF($J10=0,"",I10/$J10) | R10: =IF($J10=0,"",J10/$J10) | S10: =IF($J10=0,"",K10/$J10)
A11: 1976 | B11: 1 | C11: ='[1]11.2.2-catch'!C10/'11.6.3 Num quart long'!C10 -> 0.0092458294 | D11: ='[1]11.2.2-catch'!D10/'11.6.3 Num quart long'!D10 -> 0.35914396 | E11: ='[1]11.2.2-catch'!E10/'11.6.3 Num quart long'!E10 -> 0.30821603 | F11: ='[1]11.2.2-catch'!F10/'11.6.3 Num quart long'!F10 -> 0.29460723 | H11: =IF(C11<1,1-EXP(-C11),2) -> 0.0092032182 | I11: =IF(D11<1,1-EXP(-D11),2) -> 0.30172618 | J11: =IF(E11<1,1-EXP(-E11),2) -> 0.26524343 | K11: =IF(F11<1,1-EXP(-F11),2) -> 0.25517593 | P11: =IF($J11=0,"",H11/$J11) -> 0.034697253 | Q11: =IF($J11=0,"",I11/$J11) -> 1.1375444 | R11: =IF($J11=0,"",J11/$J11) -> 1 | S11: =IF($J11=0,"",K11/$J11) -> 0.96204431
A12: 1976 | B12: 2 | C12: ='[1]11.2.2-catch'!C11/'11.6.3 Num quart long'!C11 -> 0.049265004 | D12: ='[1]11.2.2-catch'!D11/'11.6.3 Num quart long'!D11 -> 0.38969599 | E12: ='[1]11.2.2-catch'!E11/'11.6.3 Num quart long'!E11 -> 0.52351696 | F12: ='[1]11.2.2-catch'!F11/'11.6.3 Num quart long'!F11 -> 0.40248567 | H12: =IF(C12<1,1-EXP(-C12),2) -> 0.048071168 | I12: =IF(D12<1,1-EXP(-D12),2) -> 0.32273726 | J12: =IF(E12<1,1-EXP(-E12),2) -> 0.40756669 | K12: =IF(F12<1,1-EXP(-F12),2) -> 0.33134408 | P12: =IF($J12=0,"",H12/$J12) -> 0.11794676 | Q12: =IF($J12=0,"",I12/$J12) -> 0.7918637 | R12: =IF($J12=0,"",J12/$J12) -> 1 | S12: =IF($J12=0,"",K12/$J12) -> 0.81298126
A13: 1976 | B13: 3 | C13: ='[1]11.2.2-catch'!C12/'11.6.3 Num quart long'!C12 -> 0.075318407 | D13: ='[1]11.2.2-catch'!D12/'11.6.3 Num quart long'!D12 -> 0.28240437 | E13: ='[1]11.2.2-catch'!E12/'11.6.3 Num quart long'!E12 -> 0.39032323 | F13: ='[1]11.2.2-catch'!F12/'11.6.3 Num quart long'!F12 -> 0.18269782 | H13: =IF(C13<1,1-EXP(-C13),2) -> 0.072551866 | I13: =IF(D13<1,1-EXP(-D13),2) -> 0.24603126 | J13: =IF(E13<1,1-EXP(-E13),2) -> 0.32316193 | K13: =IF(F13<1,1-EXP(-F13),2) -> 0.16698016 | P13: =IF($J13=0,"",H13/$J13) -> 0.22450623 | Q13: =IF($J13=0,"",I13/$J13) -> 0.76132502 | R13: =IF($J13=0,"",J13/$J13) -> 1 | S13: =IF($J13=0,"",K13/$J13) -> 0.51670739
A14: 1976 | B14: 4 | C14: ='[1]11.2.2-catch'!C13/'11.6.3 Num quart long'!C13 -> 0 | D14: ='[1]11.2.2-catch'!D13/'11.6.3 Num quart long'!D13 -> 0 | E14: ='[1]11.2.2-catch'!E13/'11.6.3 Num quart long'!E13 -> 0 | F14: ='[1]11.2.2-catch'!F13/'11.6.3 Num quart long'!F13 -> 0 | H14: =IF(C14<1,1-EXP(-C14),2) -> 0 | I14: =IF(D14<1,1-EXP(-D14),2) -> 0 | J14: =IF(E14<1,1-EXP(-E14),2) -> 0 | K14: =IF(F14<1,1-EXP(-F14),2) -> 0 | P14: =IF($J14=0,"",H14/$J14) | Q14: =IF($J14=0,"",I14/$J14) | R14: =IF($J14=0,"",J14/$J14) | S14: =IF($J14=0,"",K14/$J14)
... A206: 2024 | B206: 4 | C206: ='[1]11.2.2-catch'!C205/'11.6.3 Num quart long'!C205 -> 0 | D206: ='[1]11.2.2-catch'!D205/'11.6.3 Num quart long'!D205 -> 0 | E206: ='[1]11.2.2-catch'!E205/'11.6.3 Num quart long'!E205 -> 0 | F206: ='[1]11.2.2-catch'!F205/'11.6.3 Num quart long'!F205 -> 0 | H206: =IF(C206<1,1-EXP(-C206),2) -> 0 | I206: =IF(D206<1,1-EXP(-D206),2) -> 0 | J206: =IF(E206<1,1-EXP(-E206),2) -> 0 | K206: =IF(F206<1,1-EXP(-F206),2) -> 0 | P206: =IF($J206=0,"",H206/$J206) | Q206: =IF($J206=0,"",I206/$J206) | R206: =IF($J206=0,"",J206/$J206) | S206: =IF($J206=0,"",K206/$J206)
O207: Average | P207: =AVERAGE(P2:P206) -> 0.17662988 | Q207: =AVERAGE(Q2:Q206) -> 1.0093943 | R207: =AVERAGE(R2:R206) -> 1 | S207: =AVERAGE(S2:S206) -> 2.0260545

Sheet Sheet2
A1: These are proportions… | H1: These are instantaneous, if the value was > 1 I made the F be 2. | P1: What is the proption of F at age 2
A2: Year | B2: Season | C2: 0 | D2: 1 | E2: 2 | F2: 3 | H2: 0 | I2: 1 | J2: 2 | K2: 3
A3: 1974 | B3: 1 | C3: 0 | D3: 0.13413862 | E3: 0.19250449 | F3: 0.86184102 | H3: 0 | I3: 0.12553116 | J3: 0.17510938 | K3: 0.57761625 | P3: 0 | Q3: 0.71687285 | R3: 1 | S3: 3.2986025
A4: 1974 | B4: 2 | C4: 0.0075143116 | D4: 0.19322666 | E4: 0.17401659 | F4: 0.18481701 | H4: 0.0074861497 | I4: 0.17570488 | J4: 0.15971704 | K4: 0.16874362 | P4: 0.046871328 | Q4: 1.100101 | R4: 1 | S4: 1.0565161
A5: 1974 | B5: 3 | C5: 0.016472079 | D5: 0.29340907 | E5: 0.65449611 | F5: 0.33253411 | H5: 0.016337156 | I5: 0.25428297 | J5: 0.48029613 | K5: 0.28289579 | P5: 0.034014757 | Q5: 0.52942957 | R5: 1 | S5: 0.58900286
A6: 1974 | B6: 4 | C6: 0.0098722019 | D6: 0.092173232 | E6: 0.25827951 | F6: 0.25556494 | H6: 0.0098236317 | I6: 0.088052842 | J6: 0.22762069 | K6: 0.22552116 | P6: 0.043157903 | Q6: 0.38684024 | R6: 1 | S6: 0.99077621
A7: 1975 | B7: 1 | C7: 0.0004864748 | D7: 0.29525134 | E7: 0.55285431 | F7: 0.32949779 | H7: 0.00048635649 | I7: 0.25565552 | J7: 0.42469464 | K7: 0.28071513 | P7: 0.001145191 | Q7: 0.60197491 | R7: 1 | S7: 0.66098109
A8: 1975 | B8: 2 | C8: 0.0036106836 | D8: 0.38263089 | E8: 0.73654024 | F8: 0.58920958 | H8: 0.0036041729 | I8: 0.31793539 | J8: 0.52123252 | K8: 0.44523439 | P8: 0.0069147122 | Q8: 0.60996844 | R8: 1 | S8: 0.85419534
A9: 1975 | B9: 3 | C9: 0.023480913 | D9: 0.23928946 | E9: 1.5725206 | F9: 1.0671547 | H9: 0.023207381 | I9: 0.21281301 | J9: 2 | K9: 2 | P9: 0.011603691 | Q9: 0.1064065 | R9: 1 | S9: 1
A10: 1975 | B10: 4 | C10: 0 | D10: 0 | E10: 0 | F10: 0 | H10: 0 | I10: 0 | J10: 0 | K10: 0
A11: 1976 | B11: 1 | C11: 0.0092458294 | D11: 0.35914396 | E11: 0.30821603 | F11: 0.29460723 | H11: 0.0092032182 | I11: 0.30172618 | J11: 0.26524343 | K11: 0.25517593 | P11: 0.034697253 | Q11: 1.1375444 | R11: 1 | S11: 0.96204431
A12: 1976 | B12: 2 | C12: 0.049265004 | D12: 0.38969599 | E12: 0.52351696 | F12: 0.40248567 | H12: 0.048071168 | I12: 0.32273726 | J12: 0.40756669 | K12: 0.33134408 | P12: 0.11794676 | Q12: 0.7918637 | R12: 1 | S12: 0.81298126
A13: 1976 | B13: 3 | C13: 0.075318407 | D13: 0.28240437 | E13: 0.39032323 | F13: 0.18269782 | H13: 0.072551866 | I13: 0.24603126 | J13: 0.32316193 | K13: 0.16698016 | P13: 0.22450623 | Q13: 0.76132502 | R13: 1 | S13: 0.51670739
A14: 1976 | B14: 4 | C14: 0 | D14: 0 | E14: 0 | F14: 0 | H14: 0 | I14: 0 | J14: 0 | K14: 0
A15: 1977 | B15: 1 | C15: 0.0070824773 | D15: 0.2437338 | E15: 0.46137731 | F15: 0.37163423 | H15: 0.0070574556 | I15: 0.21630378 | J15: 0.36958523 | K15: 0.31039357 | P15: 0.019095611 | Q15: 0.58526088 | R15: 1 | S15: 0.839843
A16: 1977 | B16: 2 | C16: 0.0096242906 | D16: 0.20992274 | E16: 0.89868708 | F16: 0.58289917 | H16: 0.0095781254 | I16: 0.18935313 | J16: 0.5928962 | K16: 0.44172252 | P16: 0.01615481 | Q16: 0.31936978 | R16: 1 | S16: 0.74502506
A17: 1977 | B17: 3 | C17: 0.089984207 | D17: 0.15152747 | E17: 2.2531606 | F17: 1.4662275 | H17: 0.086054381 | I17: 0.14060572 | J17: 2 | K17: 2 | P17: 0.043027191 | Q17: 0.070302861 | R17: 1 | S17: 1
A18: 1977 | B18: 4 | C18: 0 | D18: 0 | E18: 0 | F18: 0 | H18: 0 | I18: 0 | J18: 0 | K18: 0
A19: 1978 | B19: 1 | C19: 0.00072488778 | D19: 0.35394913 | E19: 0.07757103 | F19: 0.23706102 | H19: 0.00072462511 | I19: 0.29808933 | J19: 0.074638706 | K19: 0.21105685 | P19: 0.0097084361 | Q19: 3.9937634 | R19: 1 | S19: 2.8277132
A20: 1978 | B20: 2 | C20: 0.012193789 | D20: 0.2163853 | E20: 0.4742481 | F20: 0.58491975 | H20: 0.012119746 | I20: 0.19457509 | J20: 0.37764717 | K20: 0.44284943 | P20: 0.032092775 | Q20: 0.51522983 | R20: 1 | S20: 1.1726539
A21: 1978 | B21: 3 | C21: 0.019429687 | D21: 0.17138297 | E21: 1.2321434 | F21: 0.43984311 | H21: 0.019242147 | I21: 0.15750114 | J21: 2 | K21: 0.35586253 | P21: 0.0096210737 | Q21: 0.078750569 | R21: 1 | S21: 0.17793126
A22: 1978 | B22: 4 | C22: 0 | D22: 0 | E22: 0 | F22: 0 | H22: 0 | I22: 0 | J22: 0 | K22: 0
A23: 1979 | B23: 1 | C23: 0.010170828 | D23: 0.21422852 | E23: 0.043832359 | F23: 0.2520148 | H23: 0.01011928 | I23: 0.19283609 | J23: 0.042885604 | K23: 0.22276677 | P23: 0.23595983 | Q23: 4.4965226 | R23: 1 | S23: 5.1944416
A24: 1979 | B24: 2 | C24: 0.0042317895 | D24: 0.11512671 | E24: 0.27242017 | F24: 0.24439201 | H24: 0.0042228481 | I24: 0.10874679 | J24: 0.23846578 | K24: 0.21681944 | P24: 0.017708403 | Q24: 0.45602683 | R24: 1 | S24: 0.90922664
A25: 1979 | B25: 3 | C25: 0.022705127 | D25: 0.10206838 | E25: 0.089024818 | F25: 0.21606238 | H25: 0.022449305 | I25: 0.097032199 | J25: 0.08517713 | K25: 0.19431496 | P25: 0.26356024 | Q25: 1.1391814 | R25: 1 | S25: 2.2813043
A26: 1979 | B26: 4 | C26: 0 | D26: 0 | E26: 0 | F26: 0 | H26: 0 | I26: 0 | J26: 0 | K26: 0
A27: 1980 | B27: 1 | C27: 0 | D27: 0.15478147 | E27: 0.5326786 | F27: 0.7434809 | H27: 0 | I27: 0.14339765 | J27: 0.41296956 | K27: 0.52454398 | P27: 0 | Q27: 0.3472354 | R27: 1 | S27: 1.2701759
A28: 1980 | B28: 2 | C28: 0 | D28: 0.28193485 | E28: 1.2876209 | F28: 1.6236609 | H28: 0 | I28: 0.24567717 | J28: 2 | K28: 2 | P28: 0 | Q28: 0.12283859 | R28: 1 | S28: 1
A29: 1980 | B29: 3 | C29: 0.027214448 | D29: 0.27562744 | E29: 0.30013017 | F29: 0.11027683 | H29: 0.026847472 | I29: 0.24090431 | J29: 0.2592782 | K29: 0.10441382 | P29: 0.10354697 | Q29: 0.92913447 | R29: 1 | S29: 0.40270961
A30: 1980 | B30: 4 | C30: 0 | D30: 0 | E30: 0 | F30: 0 | H30: 0 | I30: 0 | J30: 0 | K30: 0
A31: 1981 | B31: 1 | C31: 0.0070085831 | D31: 0.25230823 | E31: 0.24168947 | F31: 0.2568551 | H31: 0.0069840802 | I31: 0.22299479 | J31: 0.2147 | K31: 0.22651972 | P31: 0.032529484 | Q31: 1.0386343 | R31: 1 | S31: 1.0550523
A32: 1981 | B32: 2 | C32: 0.00099355432 | D32: 0.14532718 | E32: 1.1149317 | F32: 0.83495739 | H32: 0.00099306091 | I32: 0.13526068 | J32: 2 | K32: 0.56610703 | P32: 0.00049653045 | Q32: 0.067630341 | R32: 1 | S32: 0.28305352
A33: 1981 | B33: 3 | C33: 0.013305295 | D33: 0.2780245 | E33: 0.33338755 | F33: 0.11688852 | H33: 0.013217171 | I33: 0.24272173 | J33: 0.28350754 | K33: 0.11031563 | P33: 0.046620175 | Q33: 0.85613855 | R33: 1 | S33: 0.38911004
A34: 1981 | B34: 4 | C34: 0 | D34: 0 | E34: 0 | F34: 0 | H34: 0 | I34: 0 | J34: 0 | K34: 0
A35: 1982 | B35: 1 | C35: 0.014695346 | D35: 0.40702925 | E35: 0.082243081 | F35: 0.12090036 | H35: 0.014587897 | I35: 0.33437528 | J35: 0.078951958 | K35: 0.11387775 | P35: 0.18476928 | Q35: 4.235174 | R35: 1 | S35: 1.4423676
A36: 1982 | B36: 2 | C36: 0.032992668 | D36: 0.60637938 | E36: 0.30702984 | F36: 0.19847271 | H36: 0.032454346 | I36: 0.4546783 | J36: 0.26437135 | K36: 0.18001785 | P36: 0.12276045 | Q36: 1.7198471 | R36: 1 | S36: 0.68092798
A37: 1982 | B37: 3 | C37: 0.1391137 | D37: 0.075999788 | E37: 0.031915342 | F37: 0.030193237 | H37: 0.12987091 | I37: 0.073183597 | J37: 0.031411423 | K37: 0.029741974 | P37: 4.1345122 | Q37: 2.3298402 | R37: 1 | S37: 0.94685217
A38: 1982 | B38: 4 | C38: 0 | D38: 0 | E38: 0 | F38: 0 | H38: 0 | I38: 0 | J38: 0 | K38: 0
A39: 1983 | B39: 1 | C39: 0.11113146 | D39: 0.25433422 | E39: 0.30968007 | F39: 0.16914686 | H39: 0.10517889 | I39: 0.22456741 | J39: 0.26631835 | K39: 0.15561511 | P39: 0.39493671 | Q39: 0.84322919 | R39: 1 | S39: 0.5843199
A40: 1983 | B40: 2 | C40: 0.071398265 | D40: 0.27552696 | E40: 0.52502876 | F40: 0.24561867 | H40: 0.068909003 | I40: 0.24082804 | J40: 0.40846165 | K40: 0.21777955 | P40: 0.16870373 | Q40: 0.58959767 | R40: 1 | S40: 0.53317012
...
